Workbook

Sheet 🔧 Хэвлэл Админ
A1: 1
A2: Офсет хэвлэлийн бүх үнэ, материал, тохиргоог энд удирдана
A4: 1️⃣ ЕРӨНХИЙ ТОХИРГОО
A5: НӨАТ хувь | B5: 0.1 | C5: ← Өөрчлөх боломжтой
A6: Ашигийн хувь (default) | B6: 0.25 | C6: ← Тооцоолуур дээр өөрчилж болно
A7: Хаягдлын хувь | B7: 0.05 | C7: ← Цаасны нэмэлт хаягдал (5%)
A8: Хавтан (Plate) нэгж үнэ | B8: 3500 | C8: ₮/хавтан
A9: Хавтангийн тоо (өнгө бүрт) | B9: 4 | C9: ← CMYK = 4 хавтан
A10: Машин ажиллагаа (₮/бацт) | B10: 35000 | C10: ₮/бацт (500ш шилжүүлэл)
A11: Бүрэлт (Folding) ₮/хуудас | B11: 100 | C11: ₮/хуудас (A3)
A12: Тохируулгын хаягдал (хуудас/бацт) | B12: 50
A13: 2️⃣ ЦААСНЫ ТӨРӨЛ & ЗУЗААН (GSM)
A14: # | B14: Цаасны төрөл | C14: GSM | D14: Үнэ (₮/хуудас) | E14: Нэр (Dropdown-д)
A15: 1 | B15: Шохойтой цаас | C15: 80 | D15: 60
A16: 2 | B16: Шохойтой цаас | C16: 90 | D16: 70
A17: 3 | B17: Шохойтой цаас | C17: 105 | D17: 85
A18: 4 | B18: Шохойтой цаас | C18: 128 | D18: 110
A19: 5 | B19: Шохойтой цаас | C19: 157 | D19: 145
A20: 6 | B20: Шохойтой цаас | C20: 200 | D20: 200
A21: 7 | B21: Шохойтой цаас | C21: 250 | D21: 280
A22: 8 | B22: Шохойтой цаас | C22: 300 | D22: 350
A23: 9 | B23: Матт цаас | C23: 80 | D23: 65
A24: 10 | B24: Матт цаас | C24: 90 | D24: 75
A25: 11 | B25: Матт цаас | C25: 105 | D25: 90
A26: 12 | B26: Матт цаас | C26: 128 | D26: 115
... A40: 26 | B40: Хортой цаас | C40: 50 | D40: 38
A41: 27 | B41: Хатуу хавтасны картон | C41: 1.5мм | D41: 800
A42: 28 | B42: Хатуу хавтасны картон | C42: 2мм | D42: 1000
A43: 29 | B43: Хатуу хавтасны картон | C43: 2.5мм | D43: 1200
A44: 30 | B44: Кай цаас | C44: 250 | D44: 280
A45: 31 | B45: Кай цаас | C45: 300 | D45: 350
A46: 32 | B46: Стикер цаас | C46: A2 | D46: 500
A47: 33 | B47: Стикер цаас | C47: A3 | D47: 350
A49: 3️⃣ ХЭМЖЭЭ & БАЦТ
A50: # | B50: Код | C50: Нэр | D50: Өргөн (мм) | E50: Өндөр (мм) | F50: Нүүр/Бацт
A51: 1 | B51: A3 | C51: A3 (297×420мм) | D51: 297 | E51: 420 | F51: 2
A52: 2 | B52: B3 | C52: B3 (353×500мм) | D52: 353 | E52: 500 | F52: 2
A53: 3 | B53: A4 | C53: A4 (210×297мм) | D53: 210 | E53: 297 | F53: 4
A54: 4 | B54: B5 | C54: B5 (176×250мм) | D54: 176 | E54: 250 | F54: 8
A55: 5 | B55: A5 | C55: A5 (148×210мм) | D55: 148 | E55: 210 | F55: 8
...

Sheet 🔧 Хаяг Админ
A1: 🔧 ХАЯГ АДМИН — BizPrint.mn
A2: Хаяг рекламын бүтээгдэхүүн, үнэ, нэмэлт үйлчилгээг энд удирдана
A4: 1️⃣ БҮТЭЭГДЭХҮҮНИЙ ЖАГСААЛТ
A5: # | B5: Нэр | C5: М² үнэ (₮) | D5: Мин. талбай (м²)
A6: 1 | B6: Товгор үсэг | C6: 850000 | D6: 0.25
A7: 2 | B7: Нерж үсэг | C7: 1200000 | D7: 0.25
A8: 3 | B8: 3D үсэг | C8: 1500000 | D8: 0.25
A9: 4 | B9: Гэрэлт самбар | C9: 2000000 | D9: 0.5
A10: 5 | B10: PVC үсэг | C10: 600000 | D10: 0.25
A11: 6 | B11: Эпокси | C11: 1000000 | D11: 0.25
A12: 7 | B12: Фонтой хаяг | C12: 1800000 | D12: 0.5
A13: 8 | B13: Төмөр лист | C13: 1100000 | D13: 0.25
A14: 9 | B14: Лайтбокс | C14: 2500000 | D14: 0.5
A16: 2️⃣ НЭМЭЛТ СОНГОЛТУУД (Үнэд нөлөөлөх)
A17: # | B17: Нэр | C17: Үнэ (₮) | D17: Тайлбар
A18: 1 | B18: Гэрэлтүүлэг | C18: 150000 | D18: LED гэрэлтүүлэг суурилуулах
A19: 2 | B19: Төмөр рам | C19: 200000 | D19: Хаягны төмөр рам
A20: 3 | B20: Суурилуулалт | C20: 100000 | D20: Байршилд суурилуулах
A21: 4 | B21: Цагийн реле | C21: 30000 | D21: Автомат гэрэл унтраах реле
A22: 5 | B22: Тог буурулагч | C22: 35000 | D22: Тог бууруулах төхөөрөмж
A23: 6 | B23: Кран (1 цаг) | C23: 200000 | D23: 1 цагийн кран
A24: 7 | B24: Кран (өдөр) | C24: 600000 | D24: Өдрийн кран
A25: 8 | B25: Угсралт | C25: 50000 | D25: Хаяг угсралт
A26: 9 | B26: Дизайн | C26: 80000 | D26: Дизайн зураг
A28: 3️⃣ ХУГАЦААНЫ НЭМЭГДЭЛ
A29: # | B29: Нэр | C29: Нэмэгдэл %
A30: 1 | B30: Энгийн (3-5 өдөр) | C30: 0
A31: 2 | B31: 48 цаг (яаралтай) | C31: 0.15
A32: 3 | B32: 24 цаг (онцгой) | C32: 0.3
A34: 4️⃣ ЕРӨНХИЙ ТОХИРГОО
A35: НӨАТ хувь | B35: 0.1
A36: Ашигийн хувь (default) | B36: 0.25

Sheet ⚡ Хэвлэл Тооцоолуур
A1: ⚡ ХЭВЛЭЛ ТООЦООЛУУР — BizPrint.mn
A2: Офсет хэвлэлийн үнэ тооцоох • Бүх үнэ Админ-аас татагдана
A4: 📦 ОРУУЛАХ ТАЛБАР
A5: Тоо ширхэг (тираж): | B5: 500 | C5: ← тираж оруулна
A6: Нийт нүүр: | B6: 64 | C6: ← нүүрийн тоо оруулна
A7: Хэмжээ: | B7: A3 | C7: ← dropdown сонгоно
A8: Цаасны GSM: | B8: Шохойтой цаас 80гр — 60₮ | C8: ← dropdown сонгоно
A9: Өнгө: | B9: Өнгөт (4+4) | C9: ← dropdown сонгоно
A10: Хавтаслалт: | B10: Зөөлөн хавтас | C10: ← dropdown сонгоно
A11: Ашигийн хувь (%): | B11: 0.25 | C11: ← өөрчлөх боломжтой (default 25%)
A12: Хугацаа: | B12: Энгийн (3-5 өдөр) | C12: ← dropdown сонгоно
A14: 🎨 FINISHING
A15: Хавтас: | B15: Тийм | C15: ← Тийм/Үгүй
A16: Бүрэлт: | B16: Тийм | C16: ← Тийм/Үгүй
A17: Ламинац: | B17: Үгүй | C17: ← Байхгүй / Гэрэлт / Матт
A18: UV лак: | B18: Үгүй | C18: ← Тийм/Үгүй
A19: Тигел: | B19: Үгүй | C19: ← Тийм/Үгүй
A20: Эмбосс: | B20: Үгүй | C20: ← Тийм/Үгүй
A21: Хавтсын GSM: | B21: Шохойтой цаас 250гр — 280₮ | C21: ← Хавтсын цаас сонгох
A23: ⚙️ ЗАВСРЫН ТООЦОО (Автомат)
A24: Нүүр/Бацт: | B24: =IFERROR(INDEX('🔧 Хэвлэл Админ'!F51:F58,MATCH(B7,'🔧 Хэвлэл Админ'!B51:B58,0)),2) -> 2 | C24: нүүр (Админ-аас)
A25: Бацт тоо: | B25: =CEILING(B6/B24,1) -> 32 | C25: = Нийт нүүр ÷ Нүүр/Бацт (дээшээ)
A26: Өнгө үржүүлэгч: | B26: =IFERROR(INDEX('🔧 Хэвлэл Админ'!C62:C65,MATCH(B9,'🔧 Хэвлэл Админ'!B62:B65,0)),2) -> 2 | C26: = 4+4 бол 2 тал, 4+0 бол 1 тал
A27: Нийт хавтан: | B27: =B25*'🔧 Хэвлэл Админ'!B9*B26 -> 256 | C27: = Бацт × Өнгө/хавтан × үржүүлэгч
A28: Хуудас тоо (+ хаягдал): | B28: =CEILING(B5*(B6/B24)*(1+'🔧 Хэвлэл Админ'!B7),1)+B25*'🔧 Хэвлэл Админ'!B12 -> 18400 | C28: = Тираж × (Нүүрүүд/Бацт) × (1 + хаягдал%)
A29: Цаасны үнэ/хуудас: | B29: =IFERROR(INDEX('🔧 Хэвлэл Админ'!D15:D47,MATCH(B8,'🔧 Хэвлэл Админ'!E15:E47,0)),60) -> 60 | C29: = Админ цаасны хүснэгтээс
A30: Хавтсын үнэ/ш: | B30: =IFERROR(INDEX('🔧 Хэвлэл Админ'!C69:C73,MATCH(B10,'🔧 Хэвлэл Админ'!B69:B73,0)),0) -> 1200 | C30: = Хавтаслалтын үнэ (Админ-аас)
A31: Хавтсын GSM үнэ/х: | B31: =IFERROR(INDEX('🔧 Хэвлэл Админ'!D15:D47,MATCH(B21,'🔧 Хэвлэл Админ'!E15:E47,0)),280) -> 280 | C31: = Хавтсын цаасны үнэ/хуудас
A32: Хугацааны нэмэгдэл %: | B32: =IFERROR(INDEX('🔧 Хэвлэл Админ'!C85:C87,MATCH(B12,'🔧 Хэвлэл Админ'!B85:B87,0)),0) -> 0
A34: 💰 ҮНИЙН ЗАДАРГАА
A35: Зардлын нэр | B35: Тооцоо | C35: Дүн (₮) | D35: Тайлбар
A36: Хавтан (Plate) | B36: =B27&" хавтан" -> 256 хавтан | C36: =B27*'🔧 Хэвлэл Админ'!B8 -> 896000 | D36: =B27&" хавтан × "&TEXT('🔧 Хэвлэл Админ'!B8,"#,##0")&"₮" -> 256 хавтан × 3,500₮
A37: Машин ажиллагаа (Press) | B37: =B25*B26&" бацт × "&TEXT('🔧 Хэвлэл Админ'!B10,"#,##0")&"₮" -> 64 бацт × 35,000₮ | C37: =B25*B26*'🔧 Хэвлэл Админ'!B10 -> 2240000 | D37: =B25*B26&" бацт × "&TEXT('🔧 Хэвлэл Админ'!B10,"#,##0")&"₮" -> 64 бацт × 35,000₮
A38: Цаас (дотор) | B38: =TEXT(B28,"#,##0")&" хуудас" -> 18,400 хуудас | C38: =B28*B29 -> 1104000 | D38: =TEXT(B28,"#,##0")&" хуудас × "&B29&"₮" -> 18,400 хуудас × 60₮
A39: Хавтас — Хавтан | B39: =IF(OR(B10="Байхгүй",B6<=4),"-",'🔧 Хэвлэл Админ'!B9*B26&" хавтан") -> 8 хавтан | C39: =IF(OR(B10="Байхгүй",B6<=4),0,'🔧 Хэвлэл Админ'!B9*B26*'🔧 Хэвлэл Админ'!B8) -> 28000 | D39: 8 хавтан × хавтан үнэ
A40: Хавтас — Машин | B40: =IF(OR(B10="Байхгүй",B6<=4),"-",B26&" бацт") -> 2 бацт | C40: =IF(OR(B10="Байхгүй",B6<=4),0,B26*'🔧 Хэвлэл Админ'!B10) -> 70000 | D40: 1 бацт × машин үнэ
A41: Хавтас — Цаас | B41: =IF(B10="Байхгүй","-",TEXT(CEILING(B5*(1+'🔧 Хэвлэл Админ'!B7),1),"#,##0")&" хуудас") -> 525 хуудас | C41: =IF(OR(B10="Байхгүй",B6<=4),0,CEILING(B5*(1+'🔧 Хэвлэл Админ'!B7),1)*B31) -> 147000 | D41: Тираж + хаягдал × хавтсын GSM үнэ
A42: Бүрэлт (Folding) | B42: =IF(OR(B16="Үгүй",B6<=B24),"-",TEXT(B28,"#,##0")&" хуудас") -> 18,400 хуудас | C42: =IF(OR(B16="Үгүй",B6<=B24),0,B28*'🔧 Хэвлэл Админ'!B11) -> 1840000 | D42: Хуудас тоо × бүрэлт үнэ
A43: Хавтаслалт | B43: =IF(B10="Байхгүй","-",TEXT(B5,"#,##0")&" ш") -> 500 ш | C43: =IF(OR(B10="Байхгүй",B6<=4),0,B5*B30) -> 600000 | D43: =IF(B10="Байхгүй","",TEXT(B5,"#,##0")&" × "&TEXT(B30,"#,##0")&"₮") -> 500 × 1,200₮
A44: Ламинац | B44: =IF(B17="Үгүй","-",B17) -> - | C44: =IF(B17="Үгүй",0,IF(B17="Гэрэлт",'🔧 Хэвлэл Админ'!C77,'🔧 Хэвлэл Админ'!C78)*B28) -> 0 | D44: Хуудас × ламинац үнэ
...

Sheet ⚡ Хаяг Тооцоолуур
A1: ⚡ ХАЯГ ТООЦООЛУУР — BizPrint.mn
A2: Хаяг рекламын үнэ тооцоох • М² үнээр тооцоолно • Админ-аас татагдана
A4: 📦 ОРУУЛАХ ТАЛБАР
A5: Бүтээгдэхүүн: | B5: Товгор үсэг | C5: ← dropdown сонгоно
A6: Өргөн (мм): | B6: 500 | C6: ← мм-ээр оруулна
A7: Өндөр (мм): | B7: 300 | C7: ← мм-ээр оруулна
A8: Тоо ширхэг: | B8: 1 | C8: ← хаягны тоо
A9: Хугацаа: | B9: Энгийн (3-5 өдөр) | C9: ← dropdown сонгоно
A11: 🛠️ НЭМЭЛТ СОНГОЛТУУД
A12: Гэрэлтүүлэг: | B12: Үгүй | C12: ← Тийм/Үгүй
A13: Төмөр рам: | B13: Үгүй | C13: ← Тийм/Үгүй
A14: Суурилуулалт: | B14: Үгүй | C14: ← Тийм/Үгүй
A15: Цагийн реле: | B15: Үгүй | C15: ← Тийм/Үгүй
A16: Тог буурулагч: | B16: Үгүй | C16: ← Тийм/Үгүй
A17: Кран: | B17: Үгүй | C17: ← Үгүй / 1 цаг / Өдөр
A18: Угсралт: | B18: Үгүй | C18: ← Тийм/Үгүй
A19: Дизайн: | B19: Үгүй | C19: ← Тийм/Үгүй
A21: ⚙️ ТООЦОО (Автомат)
A22: М² үнэ: | B22: =IFERROR(INDEX('🔧 Хаяг Админ'!C6:C14,MATCH(B5,'🔧 Хаяг Админ'!B6:B14,0)),0) -> 850000 | C22: ₮/м² (Админ-аас)
A23: Мин. талбай: | B23: =IFERROR(INDEX('🔧 Хаяг Админ'!D6:D14,MATCH(B5,'🔧 Хаяг Админ'!B6:B14,0)),0.25) -> 0.25 | C23: м²
A24: Бодит талбай: | B24: =B6*B7/1000000 -> 0.15 | C24: м² (Өргөн × Өндөр ÷ 1,000,000)
A25: Хэрэглэх талбай: | B25: =MAX(B24,B23) -> 0.25 | C25: м² (MAX: бодит вс мин.)
A26: Хугацааны %: | B26: =IFERROR(INDEX('🔧 Хаяг Админ'!C30:C32,MATCH(B9,'🔧 Хаяг Админ'!B30:B32,0)),0) -> 0
A28: 💰 ҮНИЙН ЗАДАРГАА
A29: Зардлын нэр | B29: Тооцоо | C29: Дүн (₮) | D29: Тайлбар
A30: Үндсэн үнэ (үсэг) | B30: =TEXT(B25,"0.000")&" м² × "&B8&" ш" -> 0.250 м² × 1 ш | C30: =B25*B22*B8 -> 212500 | D30: ="Талбай × М² үнэ × Тоо" -> Талбай × М² үнэ × Тоо
A31: Гэрэлтүүлэг | B31: =IF(B12="Тийм","Тийм","-") -> - | C31: =IF(B12="Тийм",'🔧 Хаяг Админ'!C18,0) -> 0
A32: Төмөр рам | B32: =IF(B13="Тийм","Тийм","-") -> - | C32: =IF(B13="Тийм",'🔧 Хаяг Админ'!C19,0) -> 0
A33: Суурилуулалт | B33: =IF(B14="Тийм","Тийм","-") -> - | C33: =IF(B14="Тийм",'🔧 Хаяг Админ'!C20,0) -> 0
A34: Цагийн реле | B34: =IF(B15="Тийм","Тийм","-") -> - | C34: =IF(B15="Тийм",'🔧 Хаяг Админ'!C21,0) -> 0
A35: Тог буурулагч | B35: =IF(B16="Тийм","Тийм","-") -> - | C35: =IF(B16="Тийм",'🔧 Хаяг Админ'!C22,0) -> 0
A36: Кран | B36: =IF(B17="Үгүй","-",B17) -> - | C36: =IF(B17="1 цаг",'🔧 Хаяг Админ'!C23,IF(B17="Өдөр",'🔧 Хаяг Админ'!C24,0)) -> 0
A37: Угсралт | B37: =IF(B18="Тийм","Тийм","-") -> - | C37: =IF(B18="Тийм",'🔧 Хаяг Админ'!C25,0) -> 0
A38: Дизайн | B38: =IF(B19="Тийм","Тийм","-") -> - | C38: =IF(B19="Тийм",'🔧 Хаяг Админ'!C26,0) -> 0
A40: Дүн (НЭМЭЛТ-гүй) | C40: =SUM(C30:C38) -> 212500
A41: Хугацааны нэмэгдэл | B41: =IF(B26=0,"-",TEXT(B26,"0%")) -> - | C41: =C40*B26 -> 0
A43: Дүн (НӨАТ-гүй) | C43: =C40+C41 -> 212500 | D43: ₮
A44: НӨАТ (10%) | C44: =C43*'🔧 Хаяг Админ'!B35 -> 21250 | D44: ₮
A46: НИЙТ ТӨЛӨХ ДҮН | C46: =C43+C44 -> 233750 | D46: ₮

Sheet 📒 Захиалгын Түүх
A1: 📒 ЗАХИАЛГЫН ТҮҮХ — BizPrint.mn
A3: № | B3: Огноо | C3: Төрөл | D3: Үйлчлүүлэгч | E3: Утас | F3: Бүтээгдэхүүн | G3: Тоо/Тираж | H3: Дүн (НӨАТ-гүй) | I3: НӨАТ | J3: НИЙТ ДҮН | K3: Төлөв

Sheet 📋 Промпт
A1: 📋 BIZPRINT.MN — ХЭВЛЭЛ ТООЦООЛУУР ЗАСВАРЛАХ ПРОМПТ
A2: Доорх промптыг Claude-д өгч, тооцоолуурын логикийг засуулна. Промптыг бүтнээр нь хуулж өгнө.
A4: ═══════════════════════════════════════════════════════════════════
A5: ПРОМПТ ЭХЛЭЛ:
A6: ═══════════════════════════════════════════════════════════════════
A7: Чи BizPrint.mn хэвлэх үйлдвэрийн Excel тооцоолуур дээр ажиллаж байна. "⚡ Хэвлэл Тооцоолуур" шийтийн формулуудыг засаж, жижиг захиалга (флаер, брошур, тараах материал, A4/A5/A6 ар өвөргүй хэвлэл) -ээс том тиражийн ном хүртэл бүгдийг зөв тооцоолдог болго.
A9: ═══ ФАЙЛЫН БҮТЭЦ ═══
A10: • "🔧 Хэвлэл Админ" = мэдээллийн сан (үнэ, тохиргоо). ЭНД ФОРМУЛА БИЧИХГҮЙ, зөвхөн уншина.
A11: • "⚡ Хэвлэл Тооцоолуур" = калькулятор. ЗӨВХӨН ЭНД формула засна.
A13: ═══ АДМИН ШИЙТИЙН ЛАВ МЭДЭЭЛЭЛ (Уншиж ашиглах) ═══
A14: Ерөнхий тохиргоо:
A15: B5=0.1 (НӨАТ 10%), B6=0.25 (Ашиг default), B7=0.05 (Хаягдал 5%), B8=3500 (Хавтан ₮/ш), B9=4 (CMYK хавтан), B10=35000 (Машин ₮/бацт), B11=100 (Бүрэлт ₮/хуудас)
... A202: ПРОМПТ ТӨГӨСГӨЛ
